<sdf version='1.7'>
  <world name='default'>
    <physics name='default_physics' default='0' type='ode'>
      <max_step_size>0.001</max_step_size>
      <real_time_factor>1</real_time_factor>
      <real_time_update_rate>1000</real_time_update_rate>
    </physics>
    <scene>
      <ambient>0.4 0.4 0.4 1</ambient>
      <background>0.7 0.7 0.7 1</background>
      <shadows>0</shadows>
    </scene>
    <light name='sun' type='directional'>
      <cast_shadows>1</cast_shadows>
      <pose>0 0 10 0 -0 0</pose>
      <diffuse>0.8 0.8 0.8 1</diffuse>
      <specular>0.1 0.1 0.1 1</specular>
      <attenuation>
        <range>1000</range>
        <constant>0.9</constant>
        <linear>0.01</linear>
        <quadratic>0.001</quadratic>
      </attenuation>
      <direction>-0.5 0.5 -1</direction>
      <spot>
        <inner_angle>0</inner_angle>
        <outer_angle>0</outer_angle>
        <falloff>0</falloff>
      </spot>
    </light>
    <model name='miro_football_pitch'>
      <static>1</static>
      <link name='main'>
        <visual name='visual_cqr_panel'>
          <pose>-1.625 1.3 0 0 -0 1.5708</pose>
          <geometry>
            <mesh>
              <uri>model://miro_football_pitch/meshes/cqr_panel.dae</uri>
            </mesh>
          </geometry>
        </visual>
        <collision name='collision_cqr_panel'>
          <pose>-1.625 1.3 0 0 -0 1.5708</pose>
          <geometry>
            <mesh>
              <uri>model://miro_football_pitch/meshes/cqr_panel.dae</uri>
            </mesh>
          </geometry>
          <surface>
            <friction>
              <ode>
                <mu>0.1</mu>
                <mu2>0.1</mu2>
              </ode>
              <torsional>
                <ode/>
              </torsional>
            </friction>
            <contact>
              <ode/>
            </contact>
            <bounce/>
          </surface>
          <max_contacts>10</max_contacts>
        </collision>
        <visual name='visual_1'>
          <pose>-1.625 -1.3 0 0 0 -1.5708</pose>
          <geometry>
            <mesh>
              <uri>model://miro_football_pitch/meshes/cqr_panel.dae</uri>
            </mesh>
          </geometry>
        </visual>
        <collision name='collision_1'>
          <pose>-1.625 -1.3 0 0 0 -1.5708</pose>
          <geometry>
            <mesh>
              <uri>model://miro_football_pitch/meshes/cqr_panel.dae</uri>
            </mesh>
          </geometry>
          <surface>
            <friction>
              <ode>
                <mu>0.1</mu>
                <mu2>0.1</mu2>
              </ode>
              <torsional>
                <ode/>
              </torsional>
            </friction>
            <contact>
              <ode/>
            </contact>
            <bounce/>
          </surface>
          <max_contacts>10</max_contacts>
        </collision>
        <visual name='visual_2'>
          <pose>-0.975 1.3 0 0 -0 1.5708</pose>
          <geometry>
            <mesh>
              <uri>model://miro_football_pitch/meshes/cqr_panel.dae</uri>
            </mesh>
          </geometry>
        </visual>
        <collision name='collision_2'>
          <pose>-0.975 1.3 0 0 -0 1.5708</pose>
          <geometry>
            <mesh>
              <uri>model://miro_football_pitch/meshes/cqr_panel.dae</uri>
            </mesh>
          </geometry>
          <surface>
            <friction>
              <ode>
                <mu>0.1</mu>
                <mu2>0.1</mu2>
              </ode>
              <torsional>
                <ode/>
              </torsional>
            </friction>
            <contact>
              <ode/>
            </contact>
            <bounce/>
          </surface>
          <max_contacts>10</max_contacts>
        </collision>
        <visual name='visual_3'>
          <pose>-0.975 -1.3 0 0 0 -1.5708</pose>
          <geometry>
            <mesh>
              <uri>model://miro_football_pitch/meshes/cqr_panel.dae</uri>
            </mesh>
          </geometry>
        </visual>
        <collision name='collision_3'>
          <pose>-0.975 -1.3 0 0 0 -1.5708</pose>
          <geometry>
            <mesh>
              <uri>model://miro_football_pitch/meshes/cqr_panel.dae</uri>
            </mesh>
          </geometry>
          <surface>
            <friction>
              <ode>
                <mu>0.1</mu>
                <mu2>0.1</mu2>
              </ode>
              <torsional>
                <ode/>
              </torsional>
            </friction>
            <contact>
              <ode/>
            </contact>
            <bounce/>
          </surface>
          <max_contacts>10</max_contacts>
        </collision>
        <visual name='visual_4'>
          <pose>-0.325 1.3 0 0 -0 1.5708</pose>
          <geometry>
            <mesh>
              <uri>model://miro_football_pitch/meshes/cqr_panel.dae</uri>
            </mesh>
          </geometry>
        </visual>
        <collision name='collision_4'>
          <pose>-0.325 1.3 0 0 -0 1.5708</pose>
          <geometry>
            <mesh>
              <uri>model://miro_football_pitch/meshes/cqr_panel.dae</uri>
            </mesh>
          </geometry>
          <surface>
            <friction>
              <ode>
                <mu>0.1</mu>
                <mu2>0.1</mu2>
              </ode>
              <torsional>
                <ode/>
              </torsional>
            </friction>
            <contact>
              <ode/>
            </contact>
            <bounce/>
          </surface>
          <max_contacts>10</max_contacts>
        </collision>
        <visual name='visual_5'>
          <pose>-0.325 -1.3 0 0 0 -1.5708</pose>
          <geometry>
            <mesh>
              <uri>model://miro_football_pitch/meshes/cqr_panel.dae</uri>
            </mesh>
          </geometry>
        </visual>
        <collision name='collision_5'>
          <pose>-0.325 -1.3 0 0 0 -1.5708</pose>
          <geometry>
            <mesh>
              <uri>model://miro_football_pitch/meshes/cqr_panel.dae</uri>
            </mesh>
          </geometry>
          <surface>
            <friction>
              <ode>
                <mu>0.1</mu>
                <mu2>0.1</mu2>
              </ode>
              <torsional>
                <ode/>
              </torsional>
            </friction>
            <contact>
              <ode/>
            </contact>
            <bounce/>
          </surface>
          <max_contacts>10</max_contacts>
        </collision>
        <visual name='visual_6'>
          <pose>0.325 1.3 0 0 -0 1.5708</pose>
          <geometry>
            <mesh>
              <uri>model://miro_football_pitch/meshes/cqr_panel.dae</uri>
            </mesh>
          </geometry>
        </visual>
        <collision name='collision_6'>
          <pose>0.325 1.3 0 0 -0 1.5708</pose>
          <geometry>
            <mesh>
              <uri>model://miro_football_pitch/meshes/cqr_panel.dae</uri>
            </mesh>
          </geometry>
          <surface>
            <friction>
              <ode>
                <mu>0.1</mu>
                <mu2>0.1</mu2>
              </ode>
              <torsional>
                <ode/>
              </torsional>
            </friction>
            <contact>
              <ode/>
            </contact>
            <bounce/>
          </surface>
          <max_contacts>10</max_contacts>
        </collision>
        <visual name='visual_7'>
          <pose>0.325 -1.3 0 0 0 -1.5708</pose>
          <geometry>
            <mesh>
              <uri>model://miro_football_pitch/meshes/cqr_panel.dae</uri>
            </mesh>
          </geometry>
        </visual>
        <collision name='collision_7'>
          <pose>0.325 -1.3 0 0 0 -1.5708</pose>
          <geometry>
            <mesh>
              <uri>model://miro_football_pitch/meshes/cqr_panel.dae</uri>
            </mesh>
          </geometry>
          <surface>
            <friction>
              <ode>
                <mu>0.1</mu>
                <mu2>0.1</mu2>
              </ode>
              <torsional>
                <ode/>
              </torsional>
            </friction>
            <contact>
              <ode/>
            </contact>
            <bounce/>
          </surface>
          <max_contacts>10</max_contacts>
        </collision>
        <visual name='visual_8'>
          <pose>0.975 1.3 0 0 -0 1.5708</pose>
          <geometry>
            <mesh>
              <uri>model://miro_football_pitch/meshes/cqr_panel.dae</uri>
            </mesh>
          </geometry>
        </visual>
        <collision name='collision_8'>
          <pose>0.975 1.3 0 0 -0 1.5708</pose>
          <geometry>
            <mesh>
              <uri>model://miro_football_pitch/meshes/cqr_panel.dae</uri>
            </mesh>
          </geometry>
          <surface>
            <friction>
              <ode>
                <mu>0.1</mu>
                <mu2>0.1</mu2>
              </ode>
              <torsional>
                <ode/>
              </torsional>
            </friction>
            <contact>
              <ode/>
            </contact>
            <bounce/>
          </surface>
          <max_contacts>10</max_contacts>
        </collision>
        <visual name='visual_9'>
          <pose>0.975 -1.3 0 0 0 -1.5708</pose>
          <geometry>
            <mesh>
              <uri>model://miro_football_pitch/meshes/cqr_panel.dae</uri>
            </mesh>
          </geometry>
        </visual>
        <collision name='collision_9'>
          <pose>0.975 -1.3 0 0 0 -1.5708</pose>
          <geometry>
            <mesh>
              <uri>model://miro_football_pitch/meshes/cqr_panel.dae</uri>
            </mesh>
          </geometry>
          <surface>
            <friction>
              <ode>
                <mu>0.1</mu>
                <mu2>0.1</mu2>
              </ode>
              <torsional>
                <ode/>
              </torsional>
            </friction>
            <contact>
              <ode/>
            </contact>
            <bounce/>
          </surface>
          <max_contacts>10</max_contacts>
        </collision>
        <visual name='visual_10'>
          <pose>1.625 1.3 0 0 -0 1.5708</pose>
          <geometry>
            <mesh>
              <uri>model://miro_football_pitch/meshes/cqr_panel.dae</uri>
            </mesh>
          </geometry>
        </visual>
        <collision name='collision_10'>
          <pose>1.625 1.3 0 0 -0 1.5708</pose>
          <geometry>
            <mesh>
              <uri>model://miro_football_pitch/meshes/cqr_panel.dae</uri>
            </mesh>
          </geometry>
          <surface>
            <friction>
              <ode>
                <mu>0.1</mu>
                <mu2>0.1</mu2>
              </ode>
              <torsional>
                <ode/>
              </torsional>
            </friction>
            <contact>
              <ode/>
            </contact>
            <bounce/>
          </surface>
          <max_contacts>10</max_contacts>
        </collision>
        <visual name='visual_11'>
          <pose>1.625 -1.3 0 0 0 -1.5708</pose>
          <geometry>
            <mesh>
              <uri>model://miro_football_pitch/meshes/cqr_panel.dae</uri>
            </mesh>
          </geometry>
        </visual>
        <collision name='collision_11'>
          <pose>1.625 -1.3 0 0 0 -1.5708</pose>
          <geometry>
            <mesh>
              <uri>model://miro_football_pitch/meshes/cqr_panel.dae</uri>
            </mesh>
          </geometry>
          <surface>
            <friction>
              <ode>
                <mu>0.1</mu>
                <mu2>0.1</mu2>
              </ode>
              <torsional>
                <ode/>
              </torsional>
            </friction>
            <contact>
              <ode/>
            </contact>
            <bounce/>
          </surface>
          <max_contacts>10</max_contacts>
        </collision>
        <visual name='visual_12'>
          <pose>1.95 -0.975 0 0 -0 0</pose>
          <geometry>
            <mesh>
              <uri>model://miro_football_pitch/meshes/cqr_panel.dae</uri>
            </mesh>
          </geometry>
        </visual>
        <collision name='collision_12'>
          <pose>1.95 -0.975 0 0 -0 0</pose>
          <geometry>
            <mesh>
              <uri>model://miro_football_pitch/meshes/cqr_panel.dae</uri>
            </mesh>
          </geometry>
          <surface>
            <friction>
              <ode>
                <mu>0.1</mu>
                <mu2>0.1</mu2>
              </ode>
              <torsional>
                <ode/>
              </torsional>
            </friction>
            <contact>
              <ode/>
            </contact>
            <bounce/>
          </surface>
          <max_contacts>10</max_contacts>
        </collision>
        <visual name='visual_13'>
          <pose>-1.95 -0.975 0 0 -0 -3.14159</pose>
          <geometry>
            <mesh>
              <uri>model://miro_football_pitch/meshes/cqr_panel.dae</uri>
            </mesh>
          </geometry>
        </visual>
        <collision name='collision_13'>
          <pose>-1.95 -0.975 0 0 -0 -3.14159</pose>
          <geometry>
            <mesh>
              <uri>model://miro_football_pitch/meshes/cqr_panel.dae</uri>
            </mesh>
          </geometry>
          <surface>
            <friction>
              <ode>
                <mu>0.1</mu>
                <mu2>0.1</mu2>
              </ode>
              <torsional>
                <ode/>
              </torsional>
            </friction>
            <contact>
              <ode/>
            </contact>
            <bounce/>
          </surface>
          <max_contacts>10</max_contacts>
        </collision>
        <visual name='visual_14'>
          <pose>1.95 -0.325 0 0 -0 0</pose>
          <geometry>
            <mesh>
              <uri>model://miro_football_pitch/meshes/cqr_panel.dae</uri>
            </mesh>
          </geometry>
        </visual>
        <collision name='collision_14'>
          <pose>1.95 -0.325 0 0 -0 0</pose>
          <geometry>
            <mesh>
              <uri>model://miro_football_pitch/meshes/cqr_panel.dae</uri>
            </mesh>
          </geometry>
          <surface>
            <friction>
              <ode>
                <mu>0.1</mu>
                <mu2>0.1</mu2>
              </ode>
              <torsional>
                <ode/>
              </torsional>
            </friction>
            <contact>
              <ode/>
            </contact>
            <bounce/>
          </surface>
          <max_contacts>10</max_contacts>
        </collision>
        <visual name='visual_15'>
          <pose>-1.95 -0.325 0 0 -0 -3.14159</pose>
          <geometry>
            <mesh>
              <uri>model://miro_football_pitch/meshes/cqr_panel.dae</uri>
            </mesh>
          </geometry>
        </visual>
        <collision name='collision_15'>
          <pose>-1.95 -0.325 0 0 -0 -3.14159</pose>
          <geometry>
            <mesh>
              <uri>model://miro_football_pitch/meshes/cqr_panel.dae</uri>
            </mesh>
          </geometry>
          <surface>
            <friction>
              <ode>
                <mu>0.1</mu>
                <mu2>0.1</mu2>
              </ode>
              <torsional>
                <ode/>
              </torsional>
            </friction>
            <contact>
              <ode/>
            </contact>
            <bounce/>
          </surface>
          <max_contacts>10</max_contacts>
        </collision>
        <visual name='visual_16'>
          <pose>1.95 0.325 0 0 -0 0</pose>
          <geometry>
            <mesh>
              <uri>model://miro_football_pitch/meshes/cqr_panel.dae</uri>
            </mesh>
          </geometry>
        </visual>
        <collision name='collision_16'>
          <pose>1.95 0.325 0 0 -0 0</pose>
          <geometry>
            <mesh>
              <uri>model://miro_football_pitch/meshes/cqr_panel.dae</uri>
            </mesh>
          </geometry>
          <surface>
            <friction>
              <ode>
                <mu>0.1</mu>
                <mu2>0.1</mu2>
              </ode>
              <torsional>
                <ode/>
              </torsional>
            </friction>
            <contact>
              <ode/>
            </contact>
            <bounce/>
          </surface>
          <max_contacts>10</max_contacts>
        </collision>
        <visual name='visual_17'>
          <pose>-1.95 0.325 0 0 -0 -3.14159</pose>
          <geometry>
            <mesh>
              <uri>model://miro_football_pitch/meshes/cqr_panel.dae</uri>
            </mesh>
          </geometry>
        </visual>
        <collision name='collision_17'>
          <pose>-1.95 0.325 0 0 -0 -3.14159</pose>
          <geometry>
            <mesh>
              <uri>model://miro_football_pitch/meshes/cqr_panel.dae</uri>
            </mesh>
          </geometry>
          <surface>
            <friction>
              <ode>
                <mu>0.1</mu>
                <mu2>0.1</mu2>
              </ode>
              <torsional>
                <ode/>
              </torsional>
            </friction>
            <contact>
              <ode/>
            </contact>
            <bounce/>
          </surface>
          <max_contacts>10</max_contacts>
        </collision>
        <visual name='visual_18'>
          <pose>1.95 0.975 0 0 -0 0</pose>
          <geometry>
            <mesh>
              <uri>model://miro_football_pitch/meshes/cqr_panel.dae</uri>
            </mesh>
          </geometry>
        </visual>
        <collision name='collision_18'>
          <pose>1.95 0.975 0 0 -0 0</pose>
          <geometry>
            <mesh>
              <uri>model://miro_football_pitch/meshes/cqr_panel.dae</uri>
            </mesh>
          </geometry>
          <surface>
            <friction>
              <ode>
                <mu>0.1</mu>
                <mu2>0.1</mu2>
              </ode>
              <torsional>
                <ode/>
              </torsional>
            </friction>
            <contact>
              <ode/>
            </contact>
            <bounce/>
          </surface>
          <max_contacts>10</max_contacts>
        </collision>
        <visual name='visual_19'>
          <pose>-1.95 0.975 0 0 -0 -3.14159</pose>
          <geometry>
            <mesh>
              <uri>model://miro_football_pitch/meshes/cqr_panel.dae</uri>
            </mesh>
          </geometry>
        </visual>
        <collision name='collision_19'>
          <pose>-1.95 0.975 0 0 -0 -3.14159</pose>
          <geometry>
            <mesh>
              <uri>model://miro_football_pitch/meshes/cqr_panel.dae</uri>
            </mesh>
          </geometry>
          <surface>
            <friction>
              <ode>
                <mu>0.1</mu>
                <mu2>0.1</mu2>
              </ode>
              <torsional>
                <ode/>
              </torsional>
            </friction>
            <contact>
              <ode/>
            </contact>
            <bounce/>
          </surface>
          <max_contacts>10</max_contacts>
        </collision>
        <visual name='visual_20'>
          <pose>0 0 0 0 -0 0</pose>
          <geometry>
            <box>
              <size>3.9 2.6 0.01</size>
            </box>
          </geometry>
          <material>
            <script>
              <uri>file://media/materials/scripts/gazebo.material</uri>
              <name>Gazebo/Green</name>
            </script>
          </material>
        </visual>
        <collision name='collision_20'>
          <pose>0 0 0 0 -0 0</pose>
          <geometry>
            <box>
              <size>3.9 2.6 0.01</size>
            </box>
          </geometry>
          <surface>
            <friction>
              <ode>
                <mu>1</mu>
                <mu2>1</mu2>
              </ode>
              <torsional>
                <ode/>
              </torsional>
            </friction>
            <contact>
              <ode/>
            </contact>
            <bounce/>
          </surface>
          <max_contacts>10</max_contacts>
        </collision>
        <self_collide>0</self_collide>
        <enable_wind>0</enable_wind>
        <kinematic>0</kinematic>
      </link>
    </model>
    <model name='miro'>
      <frame name='miro_body::__model__' attached_to='miro_body::body'>
        <pose relative_to='__model__'>0 0 0 0 -0 0</pose>
      </frame>
      <link name='miro_body::body'>
        <inertial>
          <pose>-0.06 0 0.05 0 -0 0</pose>
          <mass>1.5708</mass>
          <inertia>
            <ixx>0.00523599</ixx>
            <ixy>0</ixy>
            <ixz>0</ixz>
            <iyy>0.00523599</iyy>
            <iyz>0</iyz>
            <izz>0.00785398</izz>
          </inertia>
        </inertial>
        <visual name='visual_valance'>
          <pose>0 0 0 0 -0 0</pose>
          <geometry>
            <mesh>
              <uri>model://miro_model/meshes/valance.dae</uri>
            </mesh>
          </geometry>
          <material>
            <script>
              <uri>file://media/materials/scripts/gazebo.material</uri>
              <name>Gazebo/Grey</name>
            </script>
          </material>
        </visual>
        <collision name='collision_valance'>
          <pose>0 0 0 0 -0 0</pose>
          <geometry>
            <mesh>
              <uri>model://miro_model/meshes/valance_collision.dae</uri>
            </mesh>
          </geometry>
          <surface>
            <friction>
              <ode>
                <mu>0.1</mu>
                <mu2>0.1</mu2>
              </ode>
              <torsional>
                <ode/>
              </torsional>
            </friction>
            <contact>
              <ode/>
            </contact>
            <bounce/>
          </surface>
          <max_contacts>10</max_contacts>
        </collision>
        <visual name='visual_skirt_lh'>
          <pose>0 0 0 0 -0 0</pose>
          <geometry>
            <mesh>
              <uri>model://miro_model/meshes/skirt_lh.dae</uri>
            </mesh>
          </geometry>
          <material>
            <script>
              <uri>file://media/materials/scripts/gazebo.material</uri>
              <name>Gazebo/Grey</name>
            </script>
          </material>
        </visual>
        <visual name='visual_skirt_rh'>
          <pose>0 0 0 0 -0 0</pose>
          <geometry>
            <mesh>
              <uri>model://miro_model/meshes/skirt_rh.dae</uri>
            </mesh>
          </geometry>
          <material>
            <script>
              <uri>file://media/materials/scripts/gazebo.material</uri>
              <name>Gazebo/Grey</name>
            </script>
          </material>
        </visual>
        <visual name='visual_cliff_sensor_L_asm'>
          <pose>0 0 0 0 -0 0</pose>
          <geometry>
            <mesh>
              <uri>model://miro_model/meshes/cliff_sensor_L_asm.dae</uri>
            </mesh>
          </geometry>
          <material>
            <script>
              <uri>file://media/materials/scripts/gazebo.material</uri>
              <name>Gazebo/DarkGrey</name>
            </script>
          </material>
        </visual>
        <visual name='visual_cliff_sensor_R_asm'>
          <pose>0 0 0 0 -0 0</pose>
          <geometry>
            <mesh>
              <uri>model://miro_model/meshes/cliff_sensor_R_asm.dae</uri>
            </mesh>
          </geometry>
          <material>
            <script>
              <uri>file://media/materials/scripts/gazebo.material</uri>
              <name>Gazebo/DarkGrey</name>
            </script>
          </material>
        </visual>
        <visual name='visual_light_sensor_holder_asm_L'>
          <pose>0 0 0 0 -0 0</pose>
          <geometry>
            <mesh>
              <uri>model://miro_model/meshes/light_sensor_holder_asm_L.dae</uri>
            </mesh>
          </geometry>
          <material>
            <script>
              <uri>file://media/materials/scripts/gazebo.material</uri>
              <name>Gazebo/DarkGrey</name>
            </script>
          </material>
        </visual>
        <visual name='visual_light_sensor_holder_asm_R'>
          <pose>0 0 0 0 -0 0</pose>
          <geometry>
            <mesh>
              <uri>model://miro_model/meshes/light_sensor_holder_asm_R.dae</uri>
            </mesh>
          </geometry>
          <material>
            <script>
              <uri>file://media/materials/scripts/gazebo.material</uri>
              <name>Gazebo/DarkGrey</name>
            </script>
          </material>
        </visual>
        <visual name='visual_body_shell'>
          <pose>0 0 0 0 -0 0</pose>
          <geometry>
            <mesh>
              <uri>model://miro_model/meshes/body_shell.dae</uri>
            </mesh>
          </geometry>
          <material>
            <script>
              <uri>file://media/materials/scripts/gazebo.material</uri>
              <name>Gazebo/White</name>
            </script>
          </material>
        </visual>
        <collision name='collision_body_shell'>
          <pose>0 0 0 0 -0 0</pose>
          <geometry>
            <mesh>
              <uri>model://miro_model/meshes/body_shell_collision.dae</uri>
            </mesh>
          </geometry>
          <surface>
            <friction>
              <ode>
                <mu>0.1</mu>
                <mu2>0.1</mu2>
              </ode>
              <torsional>
                <ode/>
              </torsional>
            </friction>
            <contact>
              <ode/>
            </contact>
            <bounce/>
          </surface>
          <max_contacts>10</max_contacts>
        </collision>
        <visual name='visual_slider'>
          <pose>0 0 0 0 -0 0</pose>
          <geometry>
            <mesh>
              <uri>model://miro_model/meshes/slider.dae</uri>
            </mesh>
          </geometry>
          <material>
            <script>
              <uri>file://media/materials/scripts/gazebo.material</uri>
              <name>Gazebo/DarkGrey</name>
            </script>
          </material>
        </visual>
        <collision name='collision_slider'>
          <pose>-0.1075 0 0.0264 0 -0 0</pose>
          <geometry>
            <sphere>
              <radius>0.015</radius>
            </sphere>
          </geometry>
          <surface>
            <friction>
              <ode>
                <mu>0.01</mu>
                <mu2>0.01</mu2>
              </ode>
              <torsional>
                <ode/>
              </torsional>
            </friction>
            <contact>
              <ode/>
            </contact>
            <bounce/>
          </surface>
          <max_contacts>10</max_contacts>
        </collision>
        <sensor name='acc_body' type='imu'>
          <pose>0 0 0 0 -0 0</pose>
          <always_on>1</always_on>
          <update_rate>50</update_rate>
          <visualize>0</visualize>
          <imu/>
        </sensor>
        <sensor name='cliff_l' type='sonar'>
          <pose>0.062 0.055 0.085 0 -0.52 0</pose>
          <always_on>1</always_on>
          <update_rate>50</update_rate>
          <visualize>0</visualize>
          <sonar>
            <min>0</min>
            <max>0.5</max>
            <radius>0.025</radius>
          </sonar>
        </sensor>
        <sensor name='cliff_r' type='sonar'>
          <pose>0.062 -0.055 0.085 0 -0.52 0</pose>
          <always_on>1</always_on>
          <update_rate>50</update_rate>
          <visualize>0</visualize>
          <sonar>
            <min>0</min>
            <max>0.5</max>
            <radius>0.025</radius>
          </sonar>
        </sensor>
        <sensor name='lightfl' type='camera'>
          <pose>0.055 0.065 0.08 -0 -0.06 0.52</pose>
          <camera>
            <horizontal_fov>1.57</horizontal_fov>
            <image>
              <width>16</width>
              <height>12</height>
            </image>
            <clip>
              <near>0.01</near>
              <far>10</far>
            </clip>
          </camera>
          <always_on>1</always_on>
          <update_rate>5</update_rate>
          <visualize>0</visualize>
        </sensor>
        <sensor name='lightfr' type='camera'>
          <pose>0.055 -0.065 0.08 0 -0.06 -0.52</pose>
          <camera>
            <horizontal_fov>1.57</horizontal_fov>
            <image>
              <width>16</width>
              <height>12</height>
            </image>
            <clip>
              <near>0.01</near>
              <far>10</far>
            </clip>
          </camera>
          <always_on>1</always_on>
          <update_rate>5</update_rate>
          <visualize>0</visualize>
        </sensor>
        <sensor name='lightrl' type='camera'>
          <pose>-0.125 0.072 0.06 0 -0.26 2.61</pose>
          <camera>
            <horizontal_fov>1.57</horizontal_fov>
            <image>
              <width>16</width>
              <height>12</height>
            </image>
            <clip>
              <near>0.01</near>
              <far>10</far>
            </clip>
          </camera>
          <always_on>1</always_on>
          <update_rate>5</update_rate>
          <visualize>0</visualize>
        </sensor>
        <sensor name='lightrr' type='camera'>
          <pose>-0.125 -0.072 0.06 0 -0.26 -2.61</pose>
          <camera>
            <horizontal_fov>1.57</horizontal_fov>
            <image>
              <width>16</width>
              <height>12</height>
            </image>
            <clip>
              <near>0.01</near>
              <far>10</far>
            </clip>
          </camera>
          <always_on>1</always_on>
          <update_rate>5</update_rate>
          <visualize>0</visualize>
        </sensor>
        <pose relative_to='miro_body::__model__'>0 0 0 0 -0 0</pose>
        <self_collide>0</self_collide>
        <enable_wind>0</enable_wind>
        <kinematic>0</kinematic>
      </link>
      <link name='miro_body::wheel_lh'>
        <inertial>
          <pose>0.00063 0.07779 0.044838 0 -0 0</pose>
          <mass>0.134041</mass>
          <inertia>
            <ixx>0.00014298</ixx>
            <ixy>0</ixy>
            <ixz>0</ixz>
            <iyy>0.00014298</iyy>
            <iyz>0</iyz>
            <izz>0.00014298</izz>
          </inertia>
        </inertial>
        <visual name='visual_wheel_tyre_lh'>
          <pose>0 0 0 0 -0 0</pose>
          <geometry>
            <mesh>
              <uri>model://miro_model/meshes/wheel_tyre_lh.dae</uri>
            </mesh>
          </geometry>
          <material>
            <script>
              <uri>file://media/materials/scripts/gazebo.material</uri>
              <name>Gazebo/DarkGrey</name>
            </script>
          </material>
        </visual>
        <collision name='collision_wheel_tyre_lh'>
          <pose>0.00063 0.07779 0.044838 -1.5446 0 0</pose>
          <geometry>
            <cylinder>
              <radius>0.045</radius>
              <length>0.002</length>
            </cylinder>
          </geometry>
          <surface>
            <friction>
              <ode>
                <mu>1</mu>
                <mu2>1</mu2>
              </ode>
              <torsional>
                <ode/>
              </torsional>
            </friction>
            <contact>
              <ode/>
            </contact>
            <bounce/>
          </surface>
          <max_contacts>10</max_contacts>
        </collision>
        <visual name='visual_wheel_rim_lh'>
          <pose>0 0 0 0 -0 0</pose>
          <geometry>
            <mesh>
              <uri>model://miro_model/meshes/wheel_rim_lh.dae</uri>
            </mesh>
          </geometry>
          <material>
            <script>
              <uri>file://media/materials/scripts/gazebo.material</uri>
              <name>Gazebo/Grey</name>
            </script>
          </material>
        </visual>
        <pose relative_to='miro_body::__model__'>0 0 0 0 -0 0</pose>
        <self_collide>0</self_collide>
        <enable_wind>0</enable_wind>
        <kinematic>0</kinematic>
      </link>
      <link name='miro_body::wheel_rh'>
        <inertial>
          <pose>0.00063 -0.07779 0.044838 0 -0 0</pose>
          <mass>0.134041</mass>
          <inertia>
            <ixx>0.00014298</ixx>
            <ixy>0</ixy>
            <ixz>0</ixz>
            <iyy>0.00014298</iyy>
            <iyz>0</iyz>
            <izz>0.00014298</izz>
          </inertia>
        </inertial>
        <visual name='visual_wheel_tyre_rh'>
          <pose>0 0 0 0 -0 0</pose>
          <geometry>
            <mesh>
              <uri>model://miro_model/meshes/wheel_tyre_rh.dae</uri>
            </mesh>
          </geometry>
          <material>
            <script>
              <uri>file://media/materials/scripts/gazebo.material</uri>
              <name>Gazebo/DarkGrey</name>
            </script>
          </material>
        </visual>
        <collision name='collision_wheel_tyre_rh'>
          <pose>0.00063 -0.07779 0.044838 1.5446 -0 0</pose>
          <geometry>
            <cylinder>
              <radius>0.045</radius>
              <length>0.002</length>
            </cylinder>
          </geometry>
          <surface>
            <friction>
              <ode>
                <mu>1</mu>
                <mu2>1</mu2>
              </ode>
              <torsional>
                <ode/>
              </torsional>
            </friction>
            <contact>
              <ode/>
            </contact>
            <bounce/>
          </surface>
          <max_contacts>10</max_contacts>
        </collision>
        <visual name='visual_wheel_rim_rh'>
          <pose>0 0 0 0 -0 0</pose>
          <geometry>
            <mesh>
              <uri>model://miro_model/meshes/wheel_rim_rh.dae</uri>
            </mesh>
          </geometry>
          <material>
            <script>
              <uri>file://media/materials/scripts/gazebo.material</uri>
              <name>Gazebo/Grey</name>
            </script>
          </material>
        </visual>
        <pose relative_to='miro_body::__model__'>0 0 0 0 -0 0</pose>
        <self_collide>0</self_collide>
        <enable_wind>0</enable_wind>
        <kinematic>0</kinematic>
      </link>
      <joint name='miro_body::body_wheel_lh' type='revolute'>
        <pose>0.00063 0.07779 0.044838 0 -0 0</pose>
        <parent>miro_body::body</parent>
        <child>miro_body::wheel_lh</child>
        <axis>
          <xyz>0 0.999657 0.026185</xyz>
          <dynamics>
            <friction>0.1</friction>
            <damping>0.1</damping>
            <spring_reference>0</spring_reference>
            <spring_stiffness>0</spring_stiffness>
          </dynamics>
          <limit>
            <lower>-1e+16</lower>
            <upper>1e+16</upper>
          </limit>
        </axis>
      </joint>
      <joint name='miro_body::body_wheel_rh' type='revolute'>
        <pose>0.00063 -0.07779 0.044838 0 -0 0</pose>
        <parent>miro_body::body</parent>
        <child>miro_body::wheel_rh</child>
        <axis>
          <xyz>0 0.999657 -0.026185</xyz>
          <dynamics>
            <friction>0.1</friction>
            <damping>0.1</damping>
            <spring_reference>0</spring_reference>
            <spring_stiffness>0</spring_stiffness>
          </dynamics>
          <limit>
            <lower>-1e+16</lower>
            <upper>1e+16</upper>
          </limit>
        </axis>
      </joint>
      <frame name='miro_tail::__model__' attached_to='miro_tail::tail_gmbl'>
        <pose relative_to='__model__'>0 0 0 0 -0 0</pose>
      </frame>
      <link name='miro_tail::tail_gmbl'>
        <inertial>
          <pose>-0.143 0 0.085 0 -0 0</pose>
          <mass>0.056549</mass>
          <inertia>
            <ixx>3.393e-05</ixx>
            <ixy>0</ixy>
            <ixz>0</ixz>
            <iyy>3.393e-05</iyy>
            <iyz>0</iyz>
            <izz>3.393e-05</izz>
          </inertia>
        </inertial>
        <pose relative_to='miro_tail::__model__'>0 0 0 0 -0 0</pose>
        <self_collide>0</self_collide>
        <enable_wind>0</enable_wind>
        <kinematic>0</kinematic>
      </link>
      <joint name='miro_tail::body_tail_gmbl' type='revolute'>
        <pose>-0.143 0 0.085 0 -0 0</pose>
        <parent>miro_body::body</parent>
        <child>miro_tail::tail_gmbl</child>
        <axis>
          <xyz>0 1 0</xyz>
          <limit>
            <lower>-1.57</lower>
            <upper>1.57</upper>
          </limit>
          <dynamics>
            <friction>0.01</friction>
            <damping>0.02</damping>
            <spring_reference>0</spring_reference>
            <spring_stiffness>0</spring_stiffness>
          </dynamics>
        </axis>
      </joint>
      <link name='miro_tail::tail'>
        <inertial>
          <pose>-0.143 0 0.085 0 -0 0</pose>
          <mass>0.056549</mass>
          <inertia>
            <ixx>3.393e-05</ixx>
            <ixy>0</ixy>
            <ixz>0</ixz>
            <iyy>3.393e-05</iyy>
            <iyz>0</iyz>
            <izz>3.393e-05</izz>
          </inertia>
        </inertial>
        <visual name='visual_tail'>
          <pose>0 0 0 0 -0 0</pose>
          <geometry>
            <mesh>
              <uri>model://miro_model/meshes/tail.dae</uri>
            </mesh>
          </geometry>
          <material>
            <script>
              <uri>file://media/materials/scripts/gazebo.material</uri>
              <name>Gazebo/Grey</name>
            </script>
          </material>
        </visual>
        <collision name='collision_tail'>
          <pose>0 0 0 0 -0 0</pose>
          <geometry>
            <mesh>
              <uri>model://miro_model/meshes/tail_collision.dae</uri>
            </mesh>
          </geometry>
          <surface>
            <friction>
              <ode>
                <mu>0.1</mu>
                <mu2>0.1</mu2>
              </ode>
              <torsional>
                <ode/>
              </torsional>
            </friction>
            <contact>
              <ode/>
            </contact>
            <bounce/>
          </surface>
          <max_contacts>10</max_contacts>
        </collision>
        <pose relative_to='miro_tail::__model__'>0 0 0 0 -0 0</pose>
        <self_collide>0</self_collide>
        <enable_wind>0</enable_wind>
        <kinematic>0</kinematic>
      </link>
      <joint name='miro_tail::tail_gmbl_tail' type='revolute'>
        <pose>-0.143 0 0.085 0 -0 0</pose>
        <parent>miro_tail::tail_gmbl</parent>
        <child>miro_tail::tail</child>
        <axis>
          <xyz>0 0 1</xyz>
          <limit>
            <lower>-1.57</lower>
            <upper>1.57</upper>
          </limit>
          <dynamics>
            <friction>0.01</friction>
            <damping>0.02</damping>
            <spring_reference>0</spring_reference>
            <spring_stiffness>0</spring_stiffness>
          </dynamics>
        </axis>
      </joint>
      <joint name='body_neck' type='revolute'>
        <pose>-0.002 0 0.081 0 -0 0</pose>
        <parent>miro_body::body</parent>
        <child>miro_neck::neck</child>
        <axis>
          <xyz>0 1 0</xyz>
          <limit>
            <lower>0</lower>
            <upper>1.57</upper>
          </limit>
          <dynamics>
            <spring_stiffness>0.4</spring_stiffness>
            <spring_reference>0</spring_reference>
            <friction>0.01</friction>
            <damping>0.1</damping>
          </dynamics>
        </axis>
      </joint>
      <frame name='miro_neck::__model__' attached_to='miro_neck::neck'>
        <pose relative_to='__model__'>0 0 0 0 -0 0</pose>
      </frame>
      <link name='miro_neck::neck'>
        <inertial>
          <pose>-0.002 0 0.141 0 -0 0</pose>
          <mass>0.075398</mass>
          <inertia>
            <ixx>9.802e-05</ixx>
            <ixy>0</ixy>
            <ixz>0</ixz>
            <iyy>9.802e-05</iyy>
            <iyz>0</iyz>
            <izz>1.508e-05</izz>
          </inertia>
        </inertial>
        <pose relative_to='miro_neck::__model__'>0 0 0 0 -0 0</pose>
        <self_collide>0</self_collide>
        <enable_wind>0</enable_wind>
        <kinematic>0</kinematic>
      </link>
      <joint name='neck_gmbl' type='revolute'>
        <pose>-0.002 0 0.201 0 -0 0</pose>
        <parent>miro_neck::neck</parent>
        <child>miro_gmbl::gmbl</child>
        <axis>
          <xyz>0 0 1</xyz>
          <limit>
            <lower>-1.57</lower>
            <upper>1.57</upper>
          </limit>
          <dynamics>
            <friction>0.01</friction>
            <damping>0.1</damping>
            <spring_reference>0</spring_reference>
            <spring_stiffness>0</spring_stiffness>
          </dynamics>
        </axis>
      </joint>
      <frame name='miro_gmbl::__model__' attached_to='miro_gmbl::gmbl'>
        <pose relative_to='__model__'>0 0 0 0 -0 0</pose>
      </frame>
      <link name='miro_gmbl::gmbl'>
        <inertial>
          <pose>-0.002 0 0.171 0 -0 0</pose>
          <mass>0.03927</mass>
          <inertia>
            <ixx>2.487e-05</ixx>
            <ixy>0</ixy>
            <ixz>0</ixz>
            <iyy>2.487e-05</iyy>
            <iyz>0</iyz>
            <izz>4.909e-05</izz>
          </inertia>
        </inertial>
        <visual name='visual_collar'>
          <pose>0 0 0 0 -0 0</pose>
          <geometry>
            <mesh>
              <uri>model://miro_model/meshes/collar.dae</uri>
            </mesh>
          </geometry>
          <material>
            <script>
              <uri>file://media/materials/scripts/gazebo.material</uri>
              <name>Gazebo/Red</name>
            </script>
          </material>
        </visual>
        <pose relative_to='miro_gmbl::__model__'>0 0 0 0 -0 0</pose>
        <self_collide>0</self_collide>
        <enable_wind>0</enable_wind>
        <kinematic>0</kinematic>
      </link>
      <joint name='gmbl_head' type='revolute'>
        <pose>-0.002 0 0.201 0 -0 0</pose>
        <parent>miro_gmbl::gmbl</parent>
        <child>miro_head::head</child>
        <axis>
          <xyz>0 1 0</xyz>
          <limit>
            <lower>-1.57</lower>
            <upper>1.57</upper>
          </limit>
          <dynamics>
            <spring_stiffness>0.1</spring_stiffness>
            <spring_reference>-0.5</spring_reference>
            <friction>0.01</friction>
            <damping>0.1</damping>
          </dynamics>
        </axis>
      </joint>
      <frame name='miro_head::__model__' attached_to='miro_head::head'>
        <pose relative_to='__model__'>0 0 0 0 -0 0</pose>
      </frame>
      <link name='miro_head::head'>
        <inertial>
          <pose>-0.002 0 0.221 0 -0 0</pose>
          <mass>0.261799</mass>
          <inertia>
            <ixx>0.00043633</ixx>
            <ixy>0</ixy>
            <ixz>0</ixz>
            <iyy>0.00043633</iyy>
            <iyz>0</iyz>
            <izz>0.00043633</izz>
          </inertia>
        </inertial>
        <visual name='visual_head_lower'>
          <pose>0 0 0 0 -0 0</pose>
          <geometry>
            <mesh>
              <uri>model://miro_model/meshes/head_lower.dae</uri>
            </mesh>
          </geometry>
          <material>
            <script>
              <uri>file://media/materials/scripts/gazebo.material</uri>
              <name>Gazebo/White</name>
            </script>
          </material>
        </visual>
        <collision name='collision_head_lower'>
          <pose>0 0 0 0 -0 0</pose>
          <geometry>
            <mesh>
              <uri>model://miro_model/meshes/head_lower_collision.dae</uri>
            </mesh>
          </geometry>
          <surface>
            <friction>
              <ode>
                <mu>0.1</mu>
                <mu2>0.1</mu2>
              </ode>
              <torsional>
                <ode/>
              </torsional>
            </friction>
            <contact>
              <ode/>
            </contact>
            <bounce/>
          </surface>
          <max_contacts>10</max_contacts>
        </collision>
        <visual name='visual_head_upper'>
          <pose>0 0 0 0 -0 0</pose>
          <geometry>
            <mesh>
              <uri>model://miro_model/meshes/head_upper.dae</uri>
            </mesh>
          </geometry>
          <material>
            <script>
              <uri>file://media/materials/scripts/gazebo.material</uri>
              <name>Gazebo/White</name>
            </script>
          </material>
        </visual>
        <collision name='collision_head_upper'>
          <pose>0 0 0 0 -0 0</pose>
          <geometry>
            <mesh>
              <uri>model://miro_model/meshes/head_upper_collision.dae</uri>
            </mesh>
          </geometry>
          <surface>
            <friction>
              <ode>
                <mu>0.1</mu>
                <mu2>0.1</mu2>
              </ode>
              <torsional>
                <ode/>
              </torsional>
            </friction>
            <contact>
              <ode/>
            </contact>
            <bounce/>
          </surface>
          <max_contacts>10</max_contacts>
        </collision>
        <visual name='visual_eyelid_lower_lh'>
          <pose>0 0 0 0 -0 0</pose>
          <geometry>
            <mesh>
              <uri>model://miro_model/meshes/eyelid_lower_lh.dae</uri>
            </mesh>
          </geometry>
          <material>
            <script>
              <uri>file://media/materials/scripts/gazebo.material</uri>
              <name>Gazebo/White</name>
            </script>
          </material>
        </visual>
        <visual name='visual_eyelid_lower_rh'>
          <pose>0 0 0 0 -0 0</pose>
          <geometry>
            <mesh>
              <uri>model://miro_model/meshes/eyelid_lower_rh.dae</uri>
            </mesh>
          </geometry>
          <material>
            <script>
              <uri>file://media/materials/scripts/gazebo.material</uri>
              <name>Gazebo/White</name>
            </script>
          </material>
        </visual>
        <visual name='visual_nose'>
          <pose>0 0 0 0 -0 0</pose>
          <geometry>
            <mesh>
              <uri>model://miro_model/meshes/nose.dae</uri>
            </mesh>
          </geometry>
          <material>
            <script>
              <uri>file://media/materials/scripts/gazebo.material</uri>
              <name>Gazebo/Grey</name>
            </script>
          </material>
        </visual>
        <collision name='collision_nose'>
          <pose>0 0 0 0 -0 0</pose>
          <geometry>
            <mesh>
              <uri>model://miro_model/meshes/nose_collision.dae</uri>
            </mesh>
          </geometry>
          <surface>
            <friction>
              <ode>
                <mu>0.3</mu>
                <mu2>0.3</mu2>
              </ode>
              <torsional>
                <ode/>
              </torsional>
            </friction>
            <contact>
              <ode/>
            </contact>
            <bounce/>
          </surface>
          <max_contacts>10</max_contacts>
        </collision>
        <visual name='visual_1'>
          <pose>0.029 0.033 0.252 0 -0 0</pose>
          <geometry>
            <sphere>
              <radius>0.018</radius>
            </sphere>
          </geometry>
          <material>
            <script>
              <uri>file://media/materials/scripts/gazebo.material</uri>
              <name>Gazebo/White</name>
            </script>
          </material>
        </visual>
        <visual name='visual_2'>
          <pose>0.0315 0.036 0.254 0 -0 0</pose>
          <geometry>
            <sphere>
              <radius>0.015</radius>
            </sphere>
          </geometry>
          <material>
            <script>
              <uri>file://media/materials/scripts/gazebo.material</uri>
              <name>Gazebo/DarkGrey</name>
            </script>
          </material>
        </visual>
        <visual name='visual_3'>
          <pose>0.029 -0.033 0.252 0 -0 0</pose>
          <geometry>
            <sphere>
              <radius>0.018</radius>
            </sphere>
          </geometry>
          <material>
            <script>
              <uri>file://media/materials/scripts/gazebo.material</uri>
              <name>Gazebo/White</name>
            </script>
          </material>
        </visual>
        <visual name='visual_4'>
          <pose>0.0315 -0.036 0.254 0 -0 0</pose>
          <geometry>
            <sphere>
              <radius>0.015</radius>
            </sphere>
          </geometry>
          <material>
            <script>
              <uri>file://media/materials/scripts/gazebo.material</uri>
              <name>Gazebo/DarkGrey</name>
            </script>
          </material>
        </visual>
        <sensor name='eye_l' type='wideanglecamera'>
          <pose>0.0377 0.0431 0.2595 -0.4262 -0.6816 0.6244</pose>
          <camera>
            <horizontal_fov>2.0944</horizontal_fov>
            <image>
              <width>1280</width>
              <height>720</height>
            </image>
            <clip>
              <near>0.006</near>
              <far>100</far>
            </clip>
            <lens>
              <type>custom</type>
              <scale_to_hfov>1</scale_to_hfov>
              <custom_function>
                <c1>2</c1>
                <c2>1.25</c2>
                <c3>0</c3>
                <f>1</f>
                <fun>sin</fun>
              </custom_function>
            </lens>
          </camera>
          <always_on>1</always_on>
          <update_rate>10</update_rate>
          <visualize>0</visualize>
        </sensor>
        <sensor name='eye_r' type='wideanglecamera'>
          <pose>0.0377 -0.0431 0.2595 0.4261 -0.6816 -0.6244</pose>
          <camera>
            <horizontal_fov>2.0944</horizontal_fov>
            <image>
              <width>1280</width>
              <height>720</height>
            </image>
            <clip>
              <near>0.006</near>
              <far>100</far>
            </clip>
            <lens>
              <type>custom</type>
              <scale_to_hfov>1</scale_to_hfov>
              <custom_function>
                <c1>2</c1>
                <c2>1.25</c2>
                <c3>0</c3>
                <f>1</f>
                <fun>sin</fun>
              </custom_function>
            </lens>
          </camera>
          <always_on>1</always_on>
          <update_rate>10</update_rate>
          <visualize>0</visualize>
        </sensor>
        <sensor name='eye_l_narrow' type='camera'>
          <pose>0.0377 0.0431 0.2595 -0.4262 -0.6816 0.6244</pose>
          <camera>
            <horizontal_fov>2.0944</horizontal_fov>
            <image>
              <width>1280</width>
              <height>720</height>
            </image>
            <clip>
              <near>0.006</near>
              <far>100</far>
            </clip>
          </camera>
          <always_on>1</always_on>
          <update_rate>10</update_rate>
          <visualize>0</visualize>
        </sensor>
        <sensor name='eye_r_narrow' type='camera'>
          <pose>0.0377 -0.0431 0.2595 0.4261 -0.6816 -0.6244</pose>
          <camera>
            <horizontal_fov>2.0944</horizontal_fov>
            <image>
              <width>1280</width>
              <height>720</height>
            </image>
            <clip>
              <near>0.006</near>
              <far>100</far>
            </clip>
          </camera>
          <always_on>1</always_on>
          <update_rate>10</update_rate>
          <visualize>0</visualize>
        </sensor>
        <sensor name='gaze' type='camera'>
          <pose>0.0577 0 0.2795 0 -0.785398 0</pose>
          <camera>
            <horizontal_fov>1</horizontal_fov>
            <image>
              <width>1280</width>
              <height>720</height>
            </image>
            <clip>
              <near>0.001</near>
              <far>100</far>
            </clip>
          </camera>
          <always_on>1</always_on>
          <update_rate>10</update_rate>
          <visualize>0</visualize>
        </sensor>
        <sensor name='overhead' type='camera'>
          <pose>0 0 1 0 1.22 0</pose>
          <camera>
            <horizontal_fov>1.0472</horizontal_fov>
            <image>
              <width>1280</width>
              <height>720</height>
            </image>
            <clip>
              <near>0.01</near>
              <far>2</far>
            </clip>
          </camera>
          <always_on>1</always_on>
          <update_rate>10</update_rate>
          <visualize>0</visualize>
        </sensor>
        <sensor name='acc_head' type='imu'>
          <pose>0 0 0 0 -0 0</pose>
          <always_on>1</always_on>
          <update_rate>50</update_rate>
          <visualize>0</visualize>
          <imu/>
        </sensor>
        <sensor name='sonar' type='sonar'>
          <pose>0.1 0 0.235 3.14159 -1.57079 3.14159</pose>
          <always_on>1</always_on>
          <update_rate>50</update_rate>
          <visualize>0</visualize>
          <sonar>
            <min>0</min>
            <max>1</max>
            <radius>0.309</radius>
          </sonar>
        </sensor>
        <pose relative_to='miro_head::__model__'>0 0 0 0 -0 0</pose>
        <self_collide>0</self_collide>
        <enable_wind>0</enable_wind>
        <kinematic>0</kinematic>
      </link>
      <link name='miro_head::eyelid_lh'>
        <inertial>
          <pose>0.029 0.032 0.252 0 -0 0</pose>
          <mass>0.016755</mass>
          <inertia>
            <ixx>4.47e-06</ixx>
            <ixy>0</ixy>
            <ixz>0</ixz>
            <iyy>4.47e-06</iyy>
            <iyz>0</iyz>
            <izz>4.47e-06</izz>
          </inertia>
        </inertial>
        <visual name='visual_eyelid_lh'>
          <pose>0 0 0 0 -0 0</pose>
          <geometry>
            <mesh>
              <uri>model://miro_model/meshes/eyelid_lh.dae</uri>
            </mesh>
          </geometry>
          <material>
            <script>
              <uri>file://media/materials/scripts/gazebo.material</uri>
              <name>Gazebo/White</name>
            </script>
          </material>
        </visual>
        <pose relative_to='miro_head::__model__'>0 0 0 0 -0 0</pose>
        <self_collide>0</self_collide>
        <enable_wind>0</enable_wind>
        <kinematic>0</kinematic>
      </link>
      <link name='miro_head::eyelid_rh'>
        <inertial>
          <pose>0.029 -0.032 0.252 0 -0 0</pose>
          <mass>0.016755</mass>
          <inertia>
            <ixx>4.47e-06</ixx>
            <ixy>0</ixy>
            <ixz>0</ixz>
            <iyy>4.47e-06</iyy>
            <iyz>0</iyz>
            <izz>4.47e-06</izz>
          </inertia>
        </inertial>
        <visual name='visual_eyelid_rh'>
          <pose>0 0 0 0 -0 0</pose>
          <geometry>
            <mesh>
              <uri>model://miro_model/meshes/eyelid_rh.dae</uri>
            </mesh>
          </geometry>
          <material>
            <script>
              <uri>file://media/materials/scripts/gazebo.material</uri>
              <name>Gazebo/White</name>
            </script>
          </material>
        </visual>
        <pose relative_to='miro_head::__model__'>0 0 0 0 -0 0</pose>
        <self_collide>0</self_collide>
        <enable_wind>0</enable_wind>
        <kinematic>0</kinematic>
      </link>
      <joint name='miro_head::head_eyelid_lh' type='revolute'>
        <pose>0.029 0.032 0.252 0 -0 0</pose>
        <parent>miro_head::head</parent>
        <child>miro_head::eyelid_lh</child>
        <axis>
          <xyz>-0.675 0.675 -0.2978</xyz>
          <limit>
            <lower>-1.57</lower>
            <upper>1.57</upper>
          </limit>
          <dynamics>
            <friction>0.1</friction>
            <damping>0.1</damping>
            <spring_reference>-0.5</spring_reference>
            <spring_stiffness>0.02</spring_stiffness>
          </dynamics>
        </axis>
        <physics>
          <ode>
            <cfm_damping>1</cfm_damping>
            <implicit_spring_damper>1</implicit_spring_damper>
            <limit>
              <cfm>0</cfm>
              <erp>0.2</erp>
            </limit>
          </ode>
        </physics>
      </joint>
      <joint name='miro_head::head_eyelid_rh' type='revolute'>
        <pose>0.029 -0.032 0.252 0 -0 0</pose>
        <parent>miro_head::head</parent>
        <child>miro_head::eyelid_rh</child>
        <axis>
          <xyz>0.675 0.675 0.2978</xyz>
          <limit>
            <lower>-1.57</lower>
            <upper>1.57</upper>
          </limit>
          <dynamics>
            <friction>0.1</friction>
            <damping>0.1</damping>
            <spring_reference>-0.5</spring_reference>
            <spring_stiffness>0.02</spring_stiffness>
          </dynamics>
        </axis>
        <physics>
          <ode>
            <cfm_damping>1</cfm_damping>
            <implicit_spring_damper>1</implicit_spring_damper>
            <limit>
              <cfm>0</cfm>
              <erp>0.2</erp>
            </limit>
          </ode>
        </physics>
      </joint>
      <link name='miro_head::ear_lh'>
        <inertial>
          <pose>-0.0437 0.0474 0.2773 0 -0 0</pose>
          <mass>0.056549</mass>
          <inertia>
            <ixx>3.393e-05</ixx>
            <ixy>0</ixy>
            <ixz>0</ixz>
            <iyy>3.393e-05</iyy>
            <iyz>0</iyz>
            <izz>3.393e-05</izz>
          </inertia>
        </inertial>
        <visual name='visual_ear_lh'>
          <pose>0 0 0 0 -0 0</pose>
          <geometry>
            <mesh>
              <uri>model://miro_model/meshes/ear_lh.dae</uri>
            </mesh>
          </geometry>
          <material>
            <script>
              <uri>file://media/materials/scripts/gazebo.material</uri>
              <name>Gazebo/Grey</name>
            </script>
          </material>
        </visual>
        <collision name='collision_ear_lh'>
          <pose>0 0 0 0 -0 0</pose>
          <geometry>
            <mesh>
              <uri>model://miro_model/meshes/ear_lh_collision.dae</uri>
            </mesh>
          </geometry>
          <surface>
            <friction>
              <ode>
                <mu>0.3</mu>
                <mu2>0.3</mu2>
              </ode>
              <torsional>
                <ode/>
              </torsional>
            </friction>
            <contact>
              <ode/>
            </contact>
            <bounce/>
          </surface>
          <max_contacts>10</max_contacts>
        </collision>
        <pose relative_to='miro_head::__model__'>0 0 0 0 -0 0</pose>
        <self_collide>0</self_collide>
        <enable_wind>0</enable_wind>
        <kinematic>0</kinematic>
      </link>
      <link name='miro_head::ear_rh'>
        <inertial>
          <pose>-0.0437 -0.0474 0.2773 0 -0 0</pose>
          <mass>0.056549</mass>
          <inertia>
            <ixx>3.393e-05</ixx>
            <ixy>0</ixy>
            <ixz>0</ixz>
            <iyy>3.393e-05</iyy>
            <iyz>0</iyz>
            <izz>3.393e-05</izz>
          </inertia>
        </inertial>
        <visual name='visual_ear_rh'>
          <pose>0 0 0 0 -0 0</pose>
          <geometry>
            <mesh>
              <uri>model://miro_model/meshes/ear_rh.dae</uri>
            </mesh>
          </geometry>
          <material>
            <script>
              <uri>file://media/materials/scripts/gazebo.material</uri>
              <name>Gazebo/Grey</name>
            </script>
          </material>
        </visual>
        <collision name='collision_ear_rh'>
          <pose>0 0 0 0 -0 0</pose>
          <geometry>
            <mesh>
              <uri>model://miro_model/meshes/ear_rh_collision.dae</uri>
            </mesh>
          </geometry>
          <surface>
            <friction>
              <ode>
                <mu>0.3</mu>
                <mu2>0.3</mu2>
              </ode>
              <torsional>
                <ode/>
              </torsional>
            </friction>
            <contact>
              <ode/>
            </contact>
            <bounce/>
          </surface>
          <max_contacts>10</max_contacts>
        </collision>
        <pose relative_to='miro_head::__model__'>0 0 0 0 -0 0</pose>
        <self_collide>0</self_collide>
        <enable_wind>0</enable_wind>
        <kinematic>0</kinematic>
      </link>
      <joint name='miro_head::head_ear_lh' type='revolute'>
        <pose>-0.0437 0.0474 0.2773 0 -0 0</pose>
        <parent>miro_head::head</parent>
        <child>miro_head::ear_lh</child>
        <axis>
          <xyz>-0.573 0.4344 0.6949</xyz>
          <limit>
            <lower>-1.57</lower>
            <upper>1.57</upper>
          </limit>
          <dynamics>
            <friction>0.01</friction>
            <damping>0.001</damping>
            <spring_reference>0</spring_reference>
            <spring_stiffness>0</spring_stiffness>
          </dynamics>
        </axis>
      </joint>
      <joint name='miro_head::head_ear_rh' type='revolute'>
        <pose>-0.0437 -0.0474 0.2773 0 -0 0</pose>
        <parent>miro_head::head</parent>
        <child>miro_head::ear_rh</child>
        <axis>
          <xyz>-0.573 -0.4344 0.6949</xyz>
          <limit>
            <lower>-1.57</lower>
            <upper>1.57</upper>
          </limit>
          <dynamics>
            <friction>0.01</friction>
            <damping>0.001</damping>
            <spring_reference>0</spring_reference>
            <spring_stiffness>0</spring_stiffness>
          </dynamics>
        </axis>
      </joint>
      <plugin name='miro_model' filename='libmiro_gazebo.so'/>
      <pose>0 0 0 0 -0 0</pose>
    </model>
    <gravity>0 0 -9.8</gravity>
    <magnetic_field>6e-06 2.3e-05 -4.2e-05</magnetic_field>
    <atmosphere type='adiabatic'/>
    <spherical_coordinates>
      <surface_model>EARTH_WGS84</surface_model>
      <latitude_deg>0</latitude_deg>
      <longitude_deg>0</longitude_deg>
      <elevation>0</elevation>
      <heading_deg>0</heading_deg>
    </spherical_coordinates>
    <gui fullscreen='0'>
      <camera name='user_camera'>
        <pose>-3.38276 -0.008237 0.816076 -0 0.315641 -0.114978</pose>
        <view_controller>orbit</view_controller>
        <projection_type>perspective</projection_type>
      </camera>
    </gui>
    <wind/>
    <model name='unit_cylinder_clone'>
      <pose>-0.988547 -0.535438 0.268445 -2.7e-05 -3.5e-05 8.6e-05</pose>
      <link name='link'>
        <inertial>
          <mass>1</mass>
          <inertia>
            <ixx>0.145833</ixx>
            <ixy>0</ixy>
            <ixz>0</ixz>
            <iyy>0.145833</iyy>
            <iyz>0</iyz>
            <izz>0.125</izz>
          </inertia>
          <pose>0 0 0 0 -0 0</pose>
        </inertial>
        <collision name='collision'>
          <geometry>
            <cylinder>
              <radius>0.132351</radius>
              <length>0.526879</length>
            </cylinder>
          </geometry>
          <max_contacts>10</max_contacts>
          <surface>
            <contact>
              <ode/>
            </contact>
            <bounce/>
            <friction>
              <torsional>
                <ode/>
              </torsional>
              <ode/>
            </friction>
          </surface>
        </collision>
        <visual name='visual'>
          <geometry>
            <cylinder>
              <radius>0.132351</radius>
              <length>0.526879</length>
            </cylinder>
          </geometry>
          <material>
            <script>
              <name>Gazebo/Grey</name>
              <uri>file://media/materials/scripts/gazebo.material</uri>
            </script>
          </material>
        </visual>
        <self_collide>0</self_collide>
        <enable_wind>0</enable_wind>
        <kinematic>0</kinematic>
      </link>
    </model>
    <model name='unit_cylinder_clone_0_clone'>
      <pose>0.506634 -0.221456 0.268446 -4.9e-05 -2e-06 0.000523</pose>
      <link name='link'>
        <inertial>
          <mass>1</mass>
          <inertia>
            <ixx>0.145833</ixx>
            <ixy>0</ixy>
            <ixz>0</ixz>
            <iyy>0.145833</iyy>
            <iyz>0</iyz>
            <izz>0.125</izz>
          </inertia>
          <pose>0 0 0 0 -0 0</pose>
        </inertial>
        <collision name='collision'>
          <geometry>
            <cylinder>
              <radius>0.132351</radius>
              <length>0.526879</length>
            </cylinder>
          </geometry>
          <max_contacts>10</max_contacts>
          <surface>
            <contact>
              <ode/>
            </contact>
            <bounce/>
            <friction>
              <torsional>
                <ode/>
              </torsional>
              <ode/>
            </friction>
          </surface>
        </collision>
        <visual name='visual'>
          <geometry>
            <cylinder>
              <radius>0.132351</radius>
              <length>0.526879</length>
            </cylinder>
          </geometry>
          <material>
            <script>
              <name>Gazebo/Grey</name>
              <uri>file://media/materials/scripts/gazebo.material</uri>
            </script>
          </material>
        </visual>
        <self_collide>0</self_collide>
        <enable_wind>0</enable_wind>
        <kinematic>0</kinematic>
      </link>
    </model>
    <model name='unit_cylinder_clone_0_clone_0'>
      <pose>1.00519 -0.939544 0.268436 -4.5e-05 1e-05 0.000524</pose>
      <link name='link'>
        <inertial>
          <mass>1</mass>
          <inertia>
            <ixx>0.145833</ixx>
            <ixy>0</ixy>
            <ixz>0</ixz>
            <iyy>0.145833</iyy>
            <iyz>0</iyz>
            <izz>0.125</izz>
          </inertia>
          <pose>0 0 0 0 -0 0</pose>
        </inertial>
        <collision name='collision'>
          <geometry>
            <cylinder>
              <radius>0.132351</radius>
              <length>0.526879</length>
            </cylinder>
          </geometry>
          <max_contacts>10</max_contacts>
          <surface>
            <contact>
              <ode/>
            </contact>
            <bounce/>
            <friction>
              <torsional>
                <ode/>
              </torsional>
              <ode/>
            </friction>
          </surface>
        </collision>
        <visual name='visual'>
          <geometry>
            <cylinder>
              <radius>0.132351</radius>
              <length>0.526879</length>
            </cylinder>
          </geometry>
          <material>
            <script>
              <name>Gazebo/Grey</name>
              <uri>file://media/materials/scripts/gazebo.material</uri>
            </script>
          </material>
        </visual>
        <self_collide>0</self_collide>
        <enable_wind>0</enable_wind>
        <kinematic>0</kinematic>
      </link>
    </model>
    <model name='unit_cylinder_clone_0_clone_1'>
      <pose>0.981062 0.892575 0.268443 -2e-06 2.6e-05 0.000525</pose>
      <link name='link'>
        <inertial>
          <mass>1</mass>
          <inertia>
            <ixx>0.145833</ixx>
            <ixy>0</ixy>
            <ixz>0</ixz>
            <iyy>0.145833</iyy>
            <iyz>0</iyz>
            <izz>0.125</izz>
          </inertia>
          <pose>0 0 0 0 -0 0</pose>
        </inertial>
        <collision name='collision'>
          <geometry>
            <cylinder>
              <radius>0.132351</radius>
              <length>0.526879</length>
            </cylinder>
          </geometry>
          <max_contacts>10</max_contacts>
          <surface>
            <contact>
              <ode/>
            </contact>
            <bounce/>
            <friction>
              <torsional>
                <ode/>
              </torsional>
              <ode/>
            </friction>
          </surface>
        </collision>
        <visual name='visual'>
          <geometry>
            <cylinder>
              <radius>0.132351</radius>
              <length>0.526879</length>
            </cylinder>
          </geometry>
          <material>
            <script>
              <name>Gazebo/Grey</name>
              <uri>file://media/materials/scripts/gazebo.material</uri>
            </script>
          </material>
        </visual>
        <self_collide>0</self_collide>
        <enable_wind>0</enable_wind>
        <kinematic>0</kinematic>
      </link>
    </model>
    <state world_name='default'>
      <sim_time>348 207000000</sim_time>
      <real_time>37 778998900</real_time>
      <wall_time>1683735735 430597800</wall_time>
      <iterations>37245</iterations>
      <model name='miro'>
        <pose>-1.00544 -0.006558 0.005364 -3.1e-05 -0.108205 -0.055221</pose>
        <scale>1 1 1</scale>
        <link name='miro_body::body'>
          <pose>-1.00544 -0.006558 0.005364 -3.1e-05 -0.108205 -0.055221</pose>
          <velocity>-3e-05 -0.002256 1.7e-05 -0.06032 0.003174 0.000541</velocity>
          <acceleration>0.055978 0.584517 0.008881 -0.812494 0.133625 -2.60085</acceleration>
          <wrench>0.08793 0.918159 0.01395 0 -0 0</wrench>
        </link>
        <link name='miro_body::wheel_lh'>
          <pose>-1.00534 -0.006572 0.005384 -0.000155 -0.110407 -0.055264</pose>
          <velocity>0.00014 -3.4e-05 -0.002706 -0.027732 0.001453 0.000569</velocity>
          <acceleration>0.119918 2.40066 -9.7519 0.908315 0.671094 1.71485</acceleration>
          <wrench>0.016074 0.321787 -1.30715 0 -0 0</wrench>
        </link>
        <link name='miro_body::wheel_rh'>
          <pose>-1.00626 -0.006501 0.005308 0.000183 -0.088915 -0.055742</pose>
          <velocity>-2.1e-05 -4.8e-05 0.002793 -0.027268 0.002986 0.000265</velocity>
          <acceleration>0.162697 2.32505 9.85862 -1.37281 -0.591965 -1.91556</acceleration>
          <wrench>0.021808 0.311652 1.32146 0 -0 0</wrench>
        </link>
        <link name='miro_gmbl::gmbl'>
          <pose>-1.05128 -0.004022 0.012682 -1.1e-05 0.473736 -0.055225</pose>
          <velocity>0.000101 0.000855 5.1e-05 -0.019558 0.002049 0.008053</velocity>
          <acceleration>0.623909 8.94961 0.011146 -0.092426 0.170301 0.662608</acceleration>
          <wrench>0.024501 0.351451 0.000438 0 -0 0</wrench>
        </link>
        <link name='miro_head::ear_lh'>
          <pose>-1.03405 0.016981 0.004906 0.044368 0.394842 -0.19353</pose>
          <velocity>0.001649 0.013624 0.000906 0.043579 -0.002756 -0.027705</velocity>
          <acceleration>2.5553 -0.634747 4.15032 -1.1181 -0.229966 1.63202</acceleration>
          <wrench>0.1445 -0.035894 0.234696 0 -0 0</wrench>
        </link>
        <link name='miro_head::ear_rh'>
          <pose>-1.03663 -0.026563 0.00497 -0.043824 0.395562 0.081683</pose>
          <velocity>0.000433 0.013588 -0.000988 0.043021 -0.002732 -0.027643</velocity>
          <acceleration>-2.66839 -0.24113 -4.0586 -2.19601 -0.337278 1.55114</acceleration>
          <wrench>-0.150895 -0.013636 -0.22951 0 -0 0</wrench>
        </link>
        <link name='miro_head::eyelid_lh'>
          <pose>-0.987473 0.059174 -0.016308 0.288208 0.196536 0.024897</pose>
          <velocity>0.002168 0.012563 0.002994 0.040787 0.000198 -0.027738</velocity>
          <acceleration>1.91245 1.238 2.90358 -0.355531 -0.751001 1.30204</acceleration>
          <wrench>0.032043 0.020743 0.048649 0 -0 0</wrench>
        </link>
        <link name='miro_head::eyelid_rh'>
          <pose>-0.968079 -0.10658 -0.01764 -0.406136 0.069411 -0.144138</pose>
          <velocity>-0.001106 0.012021 -0.004245 0.040527 -0.005226 -0.027591</velocity>
          <acceleration>-1.60909 1.45817 -2.6756 -0.896863 0.973345 1.597</acceleration>
          <wrench>-0.02696 0.024432 -0.04483 0 -0 0</wrench>
        </link>
        <link name='miro_head::head'>
          <pose>-1.05054 -0.004056 0.012315 2.4e-05 0.469661 -0.055227</pose>
          <velocity>0.001022 0.013617 -4.9e-05 0.042563 -0.002617 -0.027467</velocity>
          <acceleration>0.376959 5.03401 0.038852 -3.09652 -0.086851 1.84363</acceleration>
          <wrench>0.098688 1.3179 0.010171 0 -0 0</wrench>
        </link>
        <link name='miro_neck::neck'>
          <pose>-1.05127 -0.004024 0.012682 -1.7e-05 0.473732 -0.055217</pose>
          <velocity>-1.6e-05 -0.003415 -2.1e-05 -0.029738 0.001257 0.029652</velocity>
          <acceleration>0.260106 4.40406 0.039465 -0.257976 1.53355 1.6733</acceleration>
          <wrench>0.019611 0.332058 0.002976 0 -0 0</wrench>
        </link>
        <link name='miro_tail::tail'>
          <pose>-1.00578 -0.006542 0.004608 -2.8e-05 -0.103205 -0.055246</pose>
          <velocity>-5e-05 -0.002355 -1.5e-05 -0.0598 0.003365 5e-05</velocity>
          <acceleration>0.213331 3.52406 -0.006416 -0.342476 0.408212 0.734557</acceleration>
          <wrench>0.012064 0.199282 -0.000363 0 -0 0</wrench>
        </link>
        <link name='miro_tail::tail_gmbl'>
          <pose>-1.00578 -0.006539 0.004608 -3.1e-05 -0.103205 -0.055221</pose>
          <velocity>-5.2e-05 -0.002377 -1.6e-05 -0.060044 0.003378 4.2e-05</velocity>
          <acceleration>0.212166 3.51734 -0.009269 -0.82952 0.435136 0.720187</acceleration>
          <wrench>0.011998 0.198902 -0.000524 0 -0 0</wrench>
        </link>
      </model>
      <model name='miro_football_pitch'>
        <pose>-0.000544 -0.094575 0 0 -0 0</pose>
        <scale>1 1 1</scale>
        <link name='main'>
          <pose>-0.000544 -0.094575 0 0 -0 0</pose>
          <velocity>0 0 0 0 -0 0</velocity>
          <acceleration>0 0 0 0 -0 0</acceleration>
          <wrench>0 0 0 0 -0 0</wrench>
        </link>
      </model>
      <model name='unit_box_clone'>
        <pose>-0.190406 -0.293681 0.317961 2e-06 -9e-06 0.074911</pose>
        <scale>1 2.23218 1</scale>
        <link name='link'>
          <pose>-0.190406 -0.293681 0.317961 2e-06 -9e-06 0.074911</pose>
          <velocity>0 0 0 0 -0 0</velocity>
          <acceleration>-2.90258 -0.680566 -4.81934 -0.967161 -0.150351 3.14151</acceleration>
          <wrench>-2.90258 -0.680566 -4.81934 0 -0 0</wrench>
        </link>
      </model>
      <model name='unit_box_clone_0'>
        <pose>-0.111963 0.238134 0.317966 0 0 -0.28821</pose>
        <scale>1 2.60392 1</scale>
        <link name='link'>
          <pose>-0.111963 0.238134 0.317966 0 0 -0.28821</pose>
          <velocity>0 0 0 0 -0 0</velocity>
          <acceleration>5.88995 -0.194339 9.53984 0.620958 -0.02987 -2.4e-05</acceleration>
          <wrench>5.88995 -0.194339 9.53984 0 -0 0</wrench>
        </link>
      </model>
      <model name='unit_cylinder_clone'>
        <pose>-1.04459 -0.515627 0.268434 -9e-06 2.7e-05 0.000427</pose>
        <scale>1 1 1</scale>
        <link name='link'>
          <pose>-1.04459 -0.515627 0.268434 -9e-06 2.7e-05 0.000427</pose>
          <velocity>0 0 0 0 -0 0</velocity>
          <acceleration>0 0 -9.8 0 -0 0</acceleration>
          <wrench>0 0 -9.8 0 -0 0</wrench>
        </link>
      </model>
      <model name='unit_cylinder_clone_0_clone'>
        <pose>-0.250212 -0.976009 0.26844 -5e-06 4e-06 0.032926</pose>
        <scale>1 1 1</scale>
        <link name='link'>
          <pose>-0.250212 -0.976009 0.26844 -5e-06 4e-06 0.032926</pose>
          <velocity>0 0 0 0 -0 0</velocity>
          <acceleration>0.004595 0.008222 19.5425 -0.031208 0.017471 5e-06</acceleration>
          <wrench>0.004595 0.008222 19.5425 0 -0 0</wrench>
        </link>
      </model>
      <model name='unit_cylinder_clone_0_clone_0'>
        <pose>1.01239 -0.995304 0.26843 -2e-06 3e-06 -0.059994</pose>
        <scale>1 1 1</scale>
        <link name='link'>
          <pose>1.01239 -0.995304 0.26843 -2e-06 3e-06 -0.059994</pose>
          <velocity>0 0 0 0 -0 0</velocity>
          <acceleration>0 0 -9.8 0 -0 0</acceleration>
          <wrench>0 0 -9.8 0 -0 0</wrench>
        </link>
      </model>
      <model name='unit_cylinder_clone_0_clone_1'>
        <pose>0.981059 0.892569 0.268433 2.1e-05 9e-06 0.000522</pose>
        <scale>1 1 1</scale>
        <link name='link'>
          <pose>0.981059 0.892569 0.268433 2.1e-05 9e-06 0.000522</pose>
          <velocity>0 0 0 0 -0 0</velocity>
          <acceleration>0 0 -9.8 0 -0 0</acceleration>
          <wrench>0 0 -9.8 0 -0 0</wrench>
        </link>
      </model>
      <model name='unit_cylinder_clone_0_clone_1_clone'>
        <pose>-1.09097 0.644248 0.268436 -4.9e-05 -3e-06 0.121152</pose>
        <scale>1 1 1</scale>
        <link name='link'>
          <pose>-1.09097 0.644248 0.268436 -4.9e-05 -3e-06 0.121152</pose>
          <velocity>0 0 0 0 -0 0</velocity>
          <acceleration>0 0 -9.8 0 -0 0</acceleration>
          <wrench>0 0 -9.8 0 -0 0</wrench>
        </link>
      </model>
      <light name='sun'>
        <pose>0 0 10 0 -0 0</pose>
      </light>
    </state>
    <model name='unit_cylinder_clone_0_clone_1_clone'>
      <pose>-1.1091 0.691797 0.268445 -5e-06 4.3e-05 0.000526</pose>
      <link name='link'>
        <inertial>
          <mass>1</mass>
          <inertia>
            <ixx>0.145833</ixx>
            <ixy>0</ixy>
            <ixz>0</ixz>
            <iyy>0.145833</iyy>
            <iyz>0</iyz>
            <izz>0.125</izz>
          </inertia>
          <pose>0 0 0 0 -0 0</pose>
        </inertial>
        <collision name='collision'>
          <geometry>
            <cylinder>
              <radius>0.132351</radius>
              <length>0.526879</length>
            </cylinder>
          </geometry>
          <max_contacts>10</max_contacts>
          <surface>
            <contact>
              <ode/>
            </contact>
            <bounce/>
            <friction>
              <torsional>
                <ode/>
              </torsional>
              <ode/>
            </friction>
          </surface>
        </collision>
        <visual name='visual'>
          <geometry>
            <cylinder>
              <radius>0.132351</radius>
              <length>0.526879</length>
            </cylinder>
          </geometry>
          <material>
            <script>
              <name>Gazebo/Grey</name>
              <uri>file://media/materials/scripts/gazebo.material</uri>
            </script>
          </material>
        </visual>
        <self_collide>0</self_collide>
        <enable_wind>0</enable_wind>
        <kinematic>0</kinematic>
      </link>
    </model>
    <model name='unit_box_clone'>
      <pose>0.902793 -0.399421 0.317966 -1e-06 0 2.2e-05</pose>
      <link name='link'>
        <inertial>
          <mass>1</mass>
          <inertia>
            <ixx>0.166667</ixx>
            <ixy>0</ixy>
            <ixz>0</ixz>
            <iyy>0.166667</iyy>
            <iyz>0</iyz>
            <izz>0.166667</izz>
          </inertia>
          <pose>0 0 0 0 -0 0</pose>
        </inertial>
        <collision name='collision'>
          <geometry>
            <box>
              <size>1 0.070179 0.625932</size>
            </box>
          </geometry>
          <max_contacts>10</max_contacts>
          <surface>
            <contact>
              <ode/>
            </contact>
            <bounce/>
            <friction>
              <torsional>
                <ode/>
              </torsional>
              <ode/>
            </friction>
          </surface>
        </collision>
        <visual name='visual'>
          <geometry>
            <box>
              <size>1 0.070179 0.625932</size>
            </box>
          </geometry>
          <material>
            <script>
              <name>Gazebo/Grey</name>
              <uri>file://media/materials/scripts/gazebo.material</uri>
            </script>
          </material>
        </visual>
        <self_collide>0</self_collide>
        <enable_wind>0</enable_wind>
        <kinematic>0</kinematic>
      </link>
    </model>
    <model name='unit_box_clone_0'>
      <pose>1 0 0.317966 -1e-06 -0 2.3e-05</pose>
      <link name='link'>
        <inertial>
          <mass>1</mass>
          <inertia>
            <ixx>0.166667</ixx>
            <ixy>0</ixy>
            <ixz>0</ixz>
            <iyy>0.166667</iyy>
            <iyz>0</iyz>
            <izz>0.166667</izz>
          </inertia>
          <pose>0 0 0 0 -0 0</pose>
        </inertial>
        <collision name='collision'>
          <geometry>
            <box>
              <size>1 0.070179 0.625932</size>
            </box>
          </geometry>
          <max_contacts>10</max_contacts>
          <surface>
            <contact>
              <ode/>
            </contact>
            <bounce/>
            <friction>
              <torsional>
                <ode/>
              </torsional>
              <ode/>
            </friction>
          </surface>
        </collision>
        <visual name='visual'>
          <geometry>
            <box>
              <size>1 0.070179 0.625932</size>
            </box>
          </geometry>
          <material>
            <script>
              <name>Gazebo/Grey</name>
              <uri>file://media/materials/scripts/gazebo.material</uri>
            </script>
          </material>
        </visual>
        <self_collide>0</self_collide>
        <enable_wind>0</enable_wind>
        <kinematic>0</kinematic>
      </link>
    </model>
  </world>
</sdf>
